<?xml version="1.0" ?>
<!--
This file is used to build your robot using the URDF file format.
-->

<robot name="my_robot" xmlns:xacro="http://www.ros.org/wiki/xacro">
    
  <link name="world" />
  
  <joint name="fixed" type="fixed">
    <parent link="world" />
    <child link="base_link" />
  </joint>

    <!-- 1st link -->
  <link name="base_link">
    <static>true</static>
    <visual>
      <origin xyz="0 0 0" rpy="0 0 0"/>
      <geometry>
        <!--box size="1 1 1"/-->
        <mesh filename="package://robot_simulation/robot_description/meshes/base_link.STL" scale="0.001 0.001 0.001"/>
      </geometry>
      
      <material name="grey">
        <color rgba="0.8 0.8 0.8 1"/>
      </material>
    </visual>

    <collision>
      <origin xyz="0 0 0" rpy="0 0 0"/>
      <geometry>
        <!--box size="1 1 1"/-->
        <mesh filename="package://robot_simulation/robot_description/meshes/base_link.STL" scale="0.001 0.001 0.001"/>
      </geometry>
    </collision>

    <inertial>
      <mass value="1"/>
      <origin xyz="0 0 0.0" rpy="0 0 0"/>
      <inertia ixx="0.02" ixy="0.0" ixz="0.0" iyy="0.02" iyz="0.0" izz="0.01"/>
    </inertial>    
  </link>

  <joint name="base_to_first_joint" type="continuous">
    <origin xyz="0 0 0.130" rpy="0 0 0" />
    <parent link="base_link" />
    <child link="first_link" />

    <dynamics damping="0.001" friction="0.0" />
  </joint>

    <!-- 2nd link -->
  <link name="first_link">
    <visual>
      <origin xyz="0 0 0.300" rpy="0 0 0"/>
      <geometry>
        <!--box size="1 1 1"/-->
        <mesh filename="package://robot_simulation/robot_description/meshes/first_link.STL" scale="0.001 0.001 0.001"/>
      </geometry>
      
      <material name="grey">
        <color rgba="0.8 0.8 0.8 1"/>
      </material>
    </visual>

    <collision>
      <origin xyz="0 0 .300" rpy="0 0 0"/>
      <geometry>
        <!--box size="1 1 1"/-->
        <mesh filename="package://robot_simulation/robot_description/meshes/first_link.STL" scale="0.001 0.001 0.001"/>
      </geometry>
    </collision>

    <inertial>
      <mass value="1" />
      <origin xyz="0 0 0.300" rpy="0 0 0" />
      <inertia ixx="0.13" ixy="0.0" ixz="0.0" iyy="0.13" iyz="0.0" izz="0.0001" />
    </inertial>    
  </link>




  <!-- Need For Gazebo Integration -->

  <gazebo>
    <plugin name="gazebo_ros_control" filename="libgazebo_ros_control.so">
      <robotNamespace>/simple_model</robotNamespace>
    </plugin>
  </gazebo>

  <transmission name="base_to_first_trans">
    <type>transmission_interface/SimpleTransmission</type>
    <actuator name="motor_1">
      <mechanicalReduction>5</mechanicalReduction>
    </actuator>
    <joint name="base_to_first_joint">
      <hardwareInterface>hardware_interface/EffortJointInterface</hardwareInterface>
    </joint>
  </transmission>
</robot>